[21.08.11 23:20:46] INFO    : Initializing bot
[21.08.11 23:20:46] INFO    : Initializing vk clients
[21.08.11 23:20:47] INFO    : Logged in as: Алим Валиулин (https://vk.com/id470742863)
[21.08.11 23:20:47] INFO    : Loading plugins
[21.08.11 23:20:47] WARNING : No key specified for Yandex Speechkit Cloud. Google will be used. You can get your key - https://tech.yandex.ru/speechkit/cloud/.
[21.08.11 23:20:47] INFO    : Bot successfully initialized
[21.08.11 23:20:47] INFO    : Started to process messages
[21.08.11 23:23:28] INFO    : Initializing bot
[21.08.11 23:23:28] INFO    : Initializing vk clients
[21.08.11 23:24:06] INFO    : Initializing bot
[21.08.11 23:24:06] INFO    : Initializing vk clients
[21.08.11 23:24:06] INFO    : Logged in as: Алим Валиулин (https://vk.com/id470742863)
[21.08.11 23:24:06] INFO    : Loading plugins
[21.08.11 23:24:06] WARNING : No key specified for Yandex Speechkit Cloud. Google will be used. You can get your key - https://tech.yandex.ru/speechkit/cloud/.
[21.08.11 23:24:06] INFO    : Bot successfully initialized
[21.08.11 23:24:06] INFO    : Started to process messages
[21.08.11 23:27:26] INFO    : Initializing bot
[21.08.11 23:27:26] INFO    : Initializing vk clients
[21.08.11 23:27:27] INFO    : Logged in as: Алим Валиулин (https://vk.com/id470742863)
[21.08.11 23:27:27] INFO    : Loading plugins
[21.08.11 23:27:27] WARNING : No key specified for Yandex Speechkit Cloud. Google will be used. You can get your key - https://tech.yandex.ru/speechkit/cloud/.
[21.08.11 23:27:27] INFO    : Bot successfully initialized
[21.08.11 23:27:27] INFO    : Started to process messages
[21.08.11 23:32:19] INFO    : Initializing bot
[21.08.11 23:32:19] INFO    : Initializing vk clients
[21.08.11 23:32:19] INFO    : Logged in as: Иван Иваненко (https://vk.com/id537489641)
[21.08.11 23:32:19] INFO    : Loading plugins
[21.08.11 23:32:19] WARNING : No key specified for Yandex Speechkit Cloud. Google will be used. You can get your key - https://tech.yandex.ru/speechkit/cloud/.
[21.08.11 23:32:19] INFO    : Bot successfully initialized
[21.08.11 23:32:19] INFO    : Started to process messages
[21.08.11 23:32:24] ERROR   : Error #1
Traceback (most recent call last):
  File "C:\Users\Алим\Desktop\sketal-master\handler\handler_controller.py", line 32, in process
    res = await self.core_process(msg)
  File "C:\Users\Алим\Desktop\sketal-master\handler\handler_controller.py", line 59, in core_process
    subres = await self.process_with_plugin(msg, plugin)
  File "C:\Users\Алим\Desktop\sketal-master\handler\handler_controller.py", line 72, in process_with_plugin
    result = await plugin.process_message(msg)
  File "C:\Users\Алим\Desktop\sketal-master\plugins\multiuser\chat_random_pair.py", line 31, in process_message
    await msg.answer(f"[id{love1['id']}|{love1['first_name']} {love1['last_name']}] - {self.text} - "
KeyError: 'first_name'

[21.08.11 23:35:27] ERROR   : Errors while executing vk method:
{'error_code': 15, 'method': 'wall.get', 'error_msg': 'Access denied: this wall available only for community members'}
[21.08.11 23:35:35] ERROR   : Errors while executing vk method:
{'error_code': 15, 'method': 'wall.get', 'error_msg': 'Access denied: this wall available only for community members'}
[21.08.11 23:45:28] INFO    : Initializing bot
[21.08.11 23:45:28] INFO    : Initializing vk clients
[21.08.11 23:45:28] INFO    : Logged in as: Иван Иваненко (https://vk.com/id537489641)
[21.08.11 23:45:29] INFO    : Loading plugins
[21.08.11 23:45:29] WARNING : No key specified for Yandex Speechkit Cloud. Google will be used. You can get your key - https://tech.yandex.ru/speechkit/cloud/.
[21.08.11 23:45:29] INFO    : Bot successfully initialized
[21.08.11 23:45:29] INFO    : Started to process messages
[21.08.11 23:50:22] ERROR   : Error #1
Traceback (most recent call last):
  File "C:\Users\Алим\AppData\Local\Programs\Python\Python38\lib\site-packages\aiohttp\connector.py", line 969, in _wrap_create_connection
    return await self._loop.create_connection(*args, **kwargs)  # type: ignore  # noqa
  File "C:\Users\Алим\AppData\Local\Programs\Python\Python38\lib\asyncio\base_events.py", line 1050, in create_connection
    transport, protocol = await self._create_connection_transport(
  File "C:\Users\Алим\AppData\Local\Programs\Python\Python38\lib\asyncio\base_events.py", line 1080, in _create_connection_transport
    await waiter
ConnectionResetError

The above exception was the direct cause of the following exception:

Traceback (most recent call last):
  File "C:\Users\Алим\Desktop\sketal-master\handler\handler_controller.py", line 32, in process
    res = await self.core_process(msg)
  File "C:\Users\Алим\Desktop\sketal-master\handler\handler_controller.py", line 59, in core_process
    subres = await self.process_with_plugin(msg, plugin)
  File "C:\Users\Алим\Desktop\sketal-master\handler\handler_controller.py", line 72, in process_with_plugin
    result = await plugin.process_message(msg)
  File "C:\Users\Алим\Desktop\sketal-master\plugins\outsource\outsource_faceapp.py", line 102, in process_message
    async with sess.post(BASE_API_URL, headers=headers, data={'file': image}) as resp:
  File "C:\Users\Алим\AppData\Local\Programs\Python\Python38\lib\site-packages\aiohttp\client.py", line 1117, in __aenter__
    self._resp = await self._coro
  File "C:\Users\Алим\AppData\Local\Programs\Python\Python38\lib\site-packages\aiohttp\client.py", line 520, in _request
    conn = await self._connector.connect(
  File "C:\Users\Алим\AppData\Local\Programs\Python\Python38\lib\site-packages\aiohttp\connector.py", line 535, in connect
    proto = await self._create_connection(req, traces, timeout)
  File "C:\Users\Алим\AppData\Local\Programs\Python\Python38\lib\site-packages\aiohttp\connector.py", line 892, in _create_connection
    _, proto = await self._create_direct_connection(req, traces, timeout)
  File "C:\Users\Алим\AppData\Local\Programs\Python\Python38\lib\site-packages\aiohttp\connector.py", line 1051, in _create_direct_connection
    raise last_exc
  File "C:\Users\Алим\AppData\Local\Programs\Python\Python38\lib\site-packages\aiohttp\connector.py", line 1020, in _create_direct_connection
    transp, proto = await self._wrap_create_connection(
  File "C:\Users\Алим\AppData\Local\Programs\Python\Python38\lib\site-packages\aiohttp\connector.py", line 975, in _wrap_create_connection
    raise client_error(req.connection_key, exc) from exc
aiohttp.client_exceptions.ClientConnectorError: Cannot connect to host node-01.faceapp.io:443 ssl:default [None]

[21.08.11 23:52:10] ERROR   : Error #2
Traceback (most recent call last):
  File "C:\Users\Алим\Desktop\sketal-master\handler\handler_controller.py", line 32, in process
    res = await self.core_process(msg)
  File "C:\Users\Алим\Desktop\sketal-master\handler\handler_controller.py", line 59, in core_process
    subres = await self.process_with_plugin(msg, plugin)
  File "C:\Users\Алим\Desktop\sketal-master\handler\handler_controller.py", line 72, in process_with_plugin
    result = await plugin.process_message(msg)
  File "C:\Users\Алим\Desktop\sketal-master\plugins\multiuser\chat_random_pair.py", line 31, in process_message
    await msg.answer(f"[id{love1['id']}|{love1['first_name']} {love1['last_name']}] - {self.text} - "
KeyError: 'first_name'

[21.08.12 00:05:21] INFO    : Initializing bot
[21.08.12 00:05:21] INFO    : Initializing vk clients
[21.08.12 00:08:00] INFO    : Initializing bot
[21.08.12 00:08:00] INFO    : Initializing vk clients
[21.08.12 00:08:00] INFO    : Logged in as: Иван Иваненко (https://vk.com/id537489641)
[21.08.12 00:08:00] INFO    : Loading plugins
[21.08.12 00:08:00] WARNING : No key specified for Yandex Speechkit Cloud. Google will be used. You can get your key - https://tech.yandex.ru/speechkit/cloud/.
[21.08.12 00:08:00] INFO    : Bot successfully initialized
[21.08.12 00:08:00] INFO    : Started to process messages
[21.08.12 00:12:50] ERROR   : Error #1
Traceback (most recent call last):
  File "C:\Users\Алим\AppData\Local\Programs\Python\Python38\lib\site-packages\aiohttp\connector.py", line 969, in _wrap_create_connection
    return await self._loop.create_connection(*args, **kwargs)  # type: ignore  # noqa
  File "C:\Users\Алим\AppData\Local\Programs\Python\Python38\lib\asyncio\base_events.py", line 1050, in create_connection
    transport, protocol = await self._create_connection_transport(
  File "C:\Users\Алим\AppData\Local\Programs\Python\Python38\lib\asyncio\base_events.py", line 1080, in _create_connection_transport
    await waiter
ConnectionResetError

The above exception was the direct cause of the following exception:

Traceback (most recent call last):
  File "C:\Users\Алим\Desktop\sketal-master\handler\handler_controller.py", line 32, in process
    res = await self.core_process(msg)
  File "C:\Users\Алим\Desktop\sketal-master\handler\handler_controller.py", line 59, in core_process
    subres = await self.process_with_plugin(msg, plugin)
  File "C:\Users\Алим\Desktop\sketal-master\handler\handler_controller.py", line 72, in process_with_plugin
    result = await plugin.process_message(msg)
  File "C:\Users\Алим\Desktop\sketal-master\plugins\outsource\outsource_faceapp.py", line 102, in process_message
    async with sess.post(BASE_API_URL, headers=headers, data={'file': image}) as resp:
  File "C:\Users\Алим\AppData\Local\Programs\Python\Python38\lib\site-packages\aiohttp\client.py", line 1117, in __aenter__
    self._resp = await self._coro
  File "C:\Users\Алим\AppData\Local\Programs\Python\Python38\lib\site-packages\aiohttp\client.py", line 520, in _request
    conn = await self._connector.connect(
  File "C:\Users\Алим\AppData\Local\Programs\Python\Python38\lib\site-packages\aiohttp\connector.py", line 535, in connect
    proto = await self._create_connection(req, traces, timeout)
  File "C:\Users\Алим\AppData\Local\Programs\Python\Python38\lib\site-packages\aiohttp\connector.py", line 892, in _create_connection
    _, proto = await self._create_direct_connection(req, traces, timeout)
  File "C:\Users\Алим\AppData\Local\Programs\Python\Python38\lib\site-packages\aiohttp\connector.py", line 1051, in _create_direct_connection
    raise last_exc
  File "C:\Users\Алим\AppData\Local\Programs\Python\Python38\lib\site-packages\aiohttp\connector.py", line 1020, in _create_direct_connection
    transp, proto = await self._wrap_create_connection(
  File "C:\Users\Алим\AppData\Local\Programs\Python\Python38\lib\site-packages\aiohttp\connector.py", line 975, in _wrap_create_connection
    raise client_error(req.connection_key, exc) from exc
aiohttp.client_exceptions.ClientConnectorError: Cannot connect to host node-01.faceapp.io:443 ssl:default [None]

[21.08.12 00:40:00] INFO    : Initializing bot
[21.08.12 00:40:00] INFO    : Initializing vk clients
[21.08.12 00:40:00] INFO    : Logged in as: Иван Иваненко (https://vk.com/id537489641)
[21.08.12 00:40:00] INFO    : Loading plugins
[21.08.12 00:40:00] WARNING : No key specified for Yandex Speechkit Cloud. Google will be used. You can get your key - https://tech.yandex.ru/speechkit/cloud/.
[21.08.12 00:40:00] INFO    : Bot successfully initialized
[21.08.12 00:40:00] INFO    : Started to process messages
[21.08.12 00:41:05] ERROR   : Errors while executing vk method:
{'error_code': 15, 'method': 'messages.removeChatUser', 'error_msg': "Access denied: can't remove this user"}
[21.08.12 00:47:24] INFO    : Initializing bot
[21.08.12 00:47:24] INFO    : Initializing vk clients
[21.08.12 00:47:25] INFO    : Logged in as: Иван Иваненко (https://vk.com/id537489641)
[21.08.12 00:47:25] INFO    : Loading plugins
[21.08.12 00:47:25] WARNING : No key specified for Yandex Speechkit Cloud. Google will be used. You can get your key - https://tech.yandex.ru/speechkit/cloud/.
[21.08.12 00:47:25] INFO    : Bot successfully initialized
[21.08.12 00:47:25] INFO    : Started to process messages
[21.08.12 00:52:07] INFO    : Initializing bot
[21.08.12 00:52:07] INFO    : Initializing vk clients
[21.08.12 00:52:08] INFO    : Logged in as: Иван Иваненко (https://vk.com/id537489641)
[21.08.12 00:52:08] INFO    : Loading plugins
[21.08.12 00:52:08] WARNING : No key specified for Yandex Speechkit Cloud. Google will be used. You can get your key - https://tech.yandex.ru/speechkit/cloud/.
[21.08.12 00:52:08] INFO    : Bot successfully initialized
[21.08.12 00:52:08] INFO    : Started to process messages
[21.08.12 00:54:18] INFO    : Initializing bot
[21.08.12 00:54:18] INFO    : Initializing vk clients
[21.08.12 00:54:19] INFO    : Logged in as: Иван Иваненко (https://vk.com/id537489641)
[21.08.12 00:54:19] INFO    : Loading plugins
[21.08.12 00:54:19] WARNING : No key specified for Yandex Speechkit Cloud. Google will be used. You can get your key - https://tech.yandex.ru/speechkit/cloud/.
[21.08.12 00:54:19] INFO    : Bot successfully initialized
[21.08.12 00:54:19] INFO    : Started to process messages
[21.08.12 10:27:05] INFO    : Initializing bot
[21.08.12 10:27:05] INFO    : Initializing vk clients
[21.08.12 10:27:05] INFO    : Logged in as: thanks you (https://vk.com/club203727332)
[21.08.12 10:27:08] INFO    : Logged in as: Алим Валиулин (https://vk.com/id470742863)
[21.08.12 10:27:08] INFO    : Loading plugins
[21.08.12 10:27:08] WARNING : No key specified for Yandex Speechkit Cloud. Google will be used. You can get your key - https://tech.yandex.ru/speechkit/cloud/.
[21.08.12 10:27:08] INFO    : Bot successfully initialized
[21.08.12 10:27:08] INFO    : Started to process messages
[21.08.12 10:29:29] INFO    : Initializing bot
[21.08.12 10:29:29] INFO    : Initializing vk clients
[21.08.12 10:29:29] INFO    : Logged in as: thanks you (https://vk.com/club203727332)
[21.08.12 10:29:32] INFO    : Logged in as: Алим Валиулин (https://vk.com/id470742863)
[21.08.12 10:29:32] INFO    : Loading plugins
[21.08.12 10:29:32] WARNING : No key specified for Yandex Speechkit Cloud. Google will be used. You can get your key - https://tech.yandex.ru/speechkit/cloud/.
[21.08.12 10:29:32] INFO    : Bot successfully initialized
[21.08.12 10:29:32] INFO    : Started to process messages
[21.08.12 10:32:17] INFO    : Initializing bot
[21.08.12 10:32:17] INFO    : Initializing vk clients
[21.08.12 10:32:18] INFO    : Logged in as: Иван Иваненко (https://vk.com/id537489641)
[21.08.12 10:32:18] INFO    : Loading plugins
[21.08.12 10:32:18] WARNING : No key specified for Yandex Speechkit Cloud. Google will be used. You can get your key - https://tech.yandex.ru/speechkit/cloud/.
[21.08.12 10:32:18] INFO    : Bot successfully initialized
[21.08.12 10:32:18] INFO    : Started to process messages
[21.08.12 10:35:26] INFO    : Initializing bot
[21.08.12 10:35:26] INFO    : Initializing vk clients
[21.08.12 10:35:26] INFO    : Logged in as: Иван Иваненко (https://vk.com/id537489641)
[21.08.12 10:35:26] INFO    : Loading plugins
[21.08.12 10:35:26] WARNING : No key specified for Yandex Speechkit Cloud. Google will be used. You can get your key - https://tech.yandex.ru/speechkit/cloud/.
[21.08.12 10:35:26] INFO    : Bot successfully initialized
[21.08.12 10:35:26] INFO    : Started to process messages
[21.08.12 10:39:02] ERROR   : Error #1
Traceback (most recent call last):
  File "C:\Users\Алим\Desktop\sketal-master\handler\handler_controller.py", line 32, in process
    res = await self.core_process(msg)
  File "C:\Users\Алим\Desktop\sketal-master\handler\handler_controller.py", line 59, in core_process
    subres = await self.process_with_plugin(msg, plugin)
  File "C:\Users\Алим\Desktop\sketal-master\handler\handler_controller.py", line 72, in process_with_plugin
    result = await plugin.process_message(msg)
  File "C:\Users\Алим\Desktop\sketal-master\plugins\multiuser\chat_random_pair.py", line 31, in process_message
    await msg.answer(f"[id{love1['id']}|{love1['first_name']} {love1['last_name']}] - {self.text} - "
KeyError: 'first_name'

[21.08.12 10:39:48] ERROR   : Error #2
Traceback (most recent call last):
  File "C:\Users\Алим\Desktop\sketal-master\handler\handler_controller.py", line 32, in process
    res = await self.core_process(msg)
  File "C:\Users\Алим\Desktop\sketal-master\handler\handler_controller.py", line 59, in core_process
    subres = await self.process_with_plugin(msg, plugin)
  File "C:\Users\Алим\Desktop\sketal-master\handler\handler_controller.py", line 72, in process_with_plugin
    result = await plugin.process_message(msg)
  File "C:\Users\Алим\Desktop\sketal-master\plugins\multiuser\chat_random_pair.py", line 31, in process_message
    await msg.answer(f"[id{love1['id']}|{love1['first_name']} {love1['last_name']}] - {self.text} - "
KeyError: 'first_name'

[21.08.12 10:43:46] INFO    : Initializing bot
[21.08.12 10:43:46] INFO    : Initializing vk clients
[21.08.12 10:43:47] INFO    : Logged in as: Иван Иваненко (https://vk.com/id537489641)
[21.08.12 10:43:47] INFO    : Logged in as: thanks you (https://vk.com/club203727332)
[21.08.12 10:43:47] INFO    : Loading plugins
[21.08.12 10:43:47] WARNING : No key specified for Yandex Speechkit Cloud. Google will be used. You can get your key - https://tech.yandex.ru/speechkit/cloud/.
[21.08.12 10:43:47] INFO    : Bot successfully initialized
[21.08.12 10:43:47] INFO    : Started to process messages
[21.08.12 10:45:55] INFO    : Initializing bot
[21.08.12 10:45:55] INFO    : Initializing vk clients
[21.08.12 10:45:55] INFO    : Logged in as: thanks you (https://vk.com/club203727332)
[21.08.12 10:45:55] INFO    : Loading plugins
[21.08.12 10:45:55] WARNING : No key specified for Yandex Speechkit Cloud. Google will be used. You can get your key - https://tech.yandex.ru/speechkit/cloud/.
[21.08.12 10:45:55] INFO    : Bot successfully initialized
[21.08.12 10:45:55] INFO    : Started to process messages
[21.08.12 10:49:54] ERROR   : No account to execute: "messages.getChat"!
[21.08.12 11:28:13] ERROR   : No account to execute: "messages.getChatUsers"!
[21.08.12 11:28:13] ERROR   : Error #1
Traceback (most recent call last):
  File "C:\Users\Алим\Desktop\sketal-master\handler\handler_controller.py", line 32, in process
    res = await self.core_process(msg)
  File "C:\Users\Алим\Desktop\sketal-master\handler\handler_controller.py", line 59, in core_process
    subres = await self.process_with_plugin(msg, plugin)
  File "C:\Users\Алим\Desktop\sketal-master\handler\handler_controller.py", line 72, in process_with_plugin
    result = await plugin.process_message(msg)
  File "C:\Users\Алим\Desktop\sketal-master\plugins\multiuser\chat_random_pair.py", line 30, in process_message
    love1, love2 = random.sample(users, 2)
  File "C:\Users\Алим\AppData\Local\Programs\Python\Python38\lib\random.py", line 359, in sample
    raise TypeError("Population must be a sequence or set.  For dicts, use list(d).")
TypeError: Population must be a sequence or set.  For dicts, use list(d).

[21.08.12 11:28:46] ERROR   : No account to execute: "messages.getChatUsers"!
[21.08.12 11:28:46] ERROR   : Error #2
Traceback (most recent call last):
  File "C:\Users\Алим\Desktop\sketal-master\handler\handler_controller.py", line 32, in process
    res = await self.core_process(msg)
  File "C:\Users\Алим\Desktop\sketal-master\handler\handler_controller.py", line 59, in core_process
    subres = await self.process_with_plugin(msg, plugin)
  File "C:\Users\Алим\Desktop\sketal-master\handler\handler_controller.py", line 72, in process_with_plugin
    result = await plugin.process_message(msg)
  File "C:\Users\Алим\Desktop\sketal-master\plugins\multiuser\chat_random_pair.py", line 30, in process_message
    love1, love2 = random.sample(users, 2)
  File "C:\Users\Алим\AppData\Local\Programs\Python\Python38\lib\random.py", line 359, in sample
    raise TypeError("Population must be a sequence or set.  For dicts, use list(d).")
TypeError: Population must be a sequence or set.  For dicts, use list(d).

[21.08.12 11:29:04] ERROR   : No account to execute: "messages.getChatUsers"!
[21.08.12 11:29:04] ERROR   : Error #3
Traceback (most recent call last):
  File "C:\Users\Алим\Desktop\sketal-master\handler\handler_controller.py", line 32, in process
    res = await self.core_process(msg)
  File "C:\Users\Алим\Desktop\sketal-master\handler\handler_controller.py", line 59, in core_process
    subres = await self.process_with_plugin(msg, plugin)
  File "C:\Users\Алим\Desktop\sketal-master\handler\handler_controller.py", line 72, in process_with_plugin
    result = await plugin.process_message(msg)
  File "C:\Users\Алим\Desktop\sketal-master\plugins\multiuser\chat_random_pair.py", line 30, in process_message
    love1, love2 = random.sample(users, 2)
  File "C:\Users\Алим\AppData\Local\Programs\Python\Python38\lib\random.py", line 359, in sample
    raise TypeError("Population must be a sequence or set.  For dicts, use list(d).")
TypeError: Population must be a sequence or set.  For dicts, use list(d).

[21.08.12 11:29:52] ERROR   : No account to execute: "messages.getChatUsers"!
[21.08.12 11:29:52] ERROR   : Error #4
Traceback (most recent call last):
  File "C:\Users\Алим\Desktop\sketal-master\handler\handler_controller.py", line 32, in process
    res = await self.core_process(msg)
  File "C:\Users\Алим\Desktop\sketal-master\handler\handler_controller.py", line 59, in core_process
    subres = await self.process_with_plugin(msg, plugin)
  File "C:\Users\Алим\Desktop\sketal-master\handler\handler_controller.py", line 72, in process_with_plugin
    result = await plugin.process_message(msg)
  File "C:\Users\Алим\Desktop\sketal-master\plugins\multiuser\chat_random_pair.py", line 30, in process_message
    love1, love2 = random.sample(users, 2)
  File "C:\Users\Алим\AppData\Local\Programs\Python\Python38\lib\random.py", line 359, in sample
    raise TypeError("Population must be a sequence or set.  For dicts, use list(d).")
TypeError: Population must be a sequence or set.  For dicts, use list(d).

[21.08.12 11:30:30] INFO    : Initializing bot
[21.08.12 11:30:30] INFO    : Initializing vk clients
[21.08.12 11:30:31] INFO    : Logged in as: Иван Иваненко (https://vk.com/id537489641)
[21.08.12 11:30:31] INFO    : Loading plugins
[21.08.12 11:30:31] WARNING : No key specified for Yandex Speechkit Cloud. Google will be used. You can get your key - https://tech.yandex.ru/speechkit/cloud/.
[21.08.12 11:30:31] INFO    : Bot successfully initialized
[21.08.12 11:30:31] INFO    : Started to process messages
[21.08.12 11:31:14] ERROR   : Error #1
Traceback (most recent call last):
  File "C:\Users\Алим\Desktop\sketal-master\handler\handler_controller.py", line 32, in process
    res = await self.core_process(msg)
  File "C:\Users\Алим\Desktop\sketal-master\handler\handler_controller.py", line 59, in core_process
    subres = await self.process_with_plugin(msg, plugin)
  File "C:\Users\Алим\Desktop\sketal-master\handler\handler_controller.py", line 72, in process_with_plugin
    result = await plugin.process_message(msg)
  File "C:\Users\Алим\Desktop\sketal-master\plugins\multiuser\chat_random_pair.py", line 31, in process_message
    await msg.answer(f"[id{love1['id']}|{love1['first_name']} {love1['last_name']}] - {self.text} - "
KeyError: 'first_name'

[21.08.12 11:31:24] ERROR   : Error #2
Traceback (most recent call last):
  File "C:\Users\Алим\Desktop\sketal-master\handler\handler_controller.py", line 32, in process
    res = await self.core_process(msg)
  File "C:\Users\Алим\Desktop\sketal-master\handler\handler_controller.py", line 59, in core_process
    subres = await self.process_with_plugin(msg, plugin)
  File "C:\Users\Алим\Desktop\sketal-master\handler\handler_controller.py", line 72, in process_with_plugin
    result = await plugin.process_message(msg)
  File "C:\Users\Алим\Desktop\sketal-master\plugins\multiuser\chat_random_pair.py", line 31, in process_message
    await msg.answer(f"[id{love1['id']}|{love1['first_name']} {love1['last_name']}] - {self.text} - "
KeyError: 'first_name'

[21.08.12 11:31:52] ERROR   : Error #3
Traceback (most recent call last):
  File "C:\Users\Алим\Desktop\sketal-master\handler\handler_controller.py", line 32, in process
    res = await self.core_process(msg)
  File "C:\Users\Алим\Desktop\sketal-master\handler\handler_controller.py", line 59, in core_process
    subres = await self.process_with_plugin(msg, plugin)
  File "C:\Users\Алим\Desktop\sketal-master\handler\handler_controller.py", line 72, in process_with_plugin
    result = await plugin.process_message(msg)
  File "C:\Users\Алим\Desktop\sketal-master\plugins\multiuser\chat_random_pair.py", line 31, in process_message
    await msg.answer(f"[id{love1['id']}|{love1['first_name']} {love1['last_name']}] - {self.text} - "
KeyError: 'first_name'

[21.08.12 11:32:09] ERROR   : Error #4
Traceback (most recent call last):
  File "C:\Users\Алим\Desktop\sketal-master\handler\handler_controller.py", line 32, in process
    res = await self.core_process(msg)
  File "C:\Users\Алим\Desktop\sketal-master\handler\handler_controller.py", line 59, in core_process
    subres = await self.process_with_plugin(msg, plugin)
  File "C:\Users\Алим\Desktop\sketal-master\handler\handler_controller.py", line 72, in process_with_plugin
    result = await plugin.process_message(msg)
  File "C:\Users\Алим\Desktop\sketal-master\plugins\multiuser\chat_random_pair.py", line 31, in process_message
    await msg.answer(f"[id{love1['id']}|{love1['first_name']} {love1['last_name']}] - {self.text} - "
KeyError: 'first_name'

[21.08.12 11:32:15] ERROR   : Error #5
Traceback (most recent call last):
  File "C:\Users\Алим\Desktop\sketal-master\handler\handler_controller.py", line 32, in process
    res = await self.core_process(msg)
  File "C:\Users\Алим\Desktop\sketal-master\handler\handler_controller.py", line 59, in core_process
    subres = await self.process_with_plugin(msg, plugin)
  File "C:\Users\Алим\Desktop\sketal-master\handler\handler_controller.py", line 72, in process_with_plugin
    result = await plugin.process_message(msg)
  File "C:\Users\Алим\Desktop\sketal-master\plugins\multiuser\chat_random_pair.py", line 31, in process_message
    await msg.answer(f"[id{love1['id']}|{love1['first_name']} {love1['last_name']}] - {self.text} - "
KeyError: 'first_name'

[21.08.12 11:32:43] ERROR   : Error #6
Traceback (most recent call last):
  File "C:\Users\Алим\Desktop\sketal-master\handler\handler_controller.py", line 32, in process
    res = await self.core_process(msg)
  File "C:\Users\Алим\Desktop\sketal-master\handler\handler_controller.py", line 59, in core_process
    subres = await self.process_with_plugin(msg, plugin)
  File "C:\Users\Алим\Desktop\sketal-master\handler\handler_controller.py", line 72, in process_with_plugin
    result = await plugin.process_message(msg)
  File "C:\Users\Алим\Desktop\sketal-master\plugins\multiuser\chat_random_pair.py", line 31, in process_message
    await msg.answer(f"[id{love1['id']}|{love1['first_name']} {love1['last_name']}] - {self.text} - "
KeyError: 'first_name'

[21.08.12 11:32:53] ERROR   : Error #7
Traceback (most recent call last):
  File "C:\Users\Алим\Desktop\sketal-master\handler\handler_controller.py", line 32, in process
    res = await self.core_process(msg)
  File "C:\Users\Алим\Desktop\sketal-master\handler\handler_controller.py", line 59, in core_process
    subres = await self.process_with_plugin(msg, plugin)
  File "C:\Users\Алим\Desktop\sketal-master\handler\handler_controller.py", line 72, in process_with_plugin
    result = await plugin.process_message(msg)
  File "C:\Users\Алим\Desktop\sketal-master\plugins\multiuser\chat_random_pair.py", line 31, in process_message
    await msg.answer(f"[id{love1['id']}|{love1['first_name']} {love1['last_name']}] - {self.text} - "
KeyError: 'first_name'

[21.08.12 11:33:52] ERROR   : Error #9
Traceback (most recent call last):
  File "C:\Users\Алим\Desktop\sketal-master\handler\handler_controller.py", line 32, in process
    res = await self.core_process(msg)
  File "C:\Users\Алим\Desktop\sketal-master\handler\handler_controller.py", line 59, in core_process
    subres = await self.process_with_plugin(msg, plugin)
  File "C:\Users\Алим\Desktop\sketal-master\handler\handler_controller.py", line 72, in process_with_plugin
    result = await plugin.process_message(msg)
  File "C:\Users\Алим\Desktop\sketal-master\plugins\multiuser\chat_random_pair.py", line 31, in process_message
    await msg.answer(f"[id{love1['id']}|{love1['first_name']} {love1['last_name']}] - {self.text} - "
KeyError: 'first_name'

[21.08.12 11:35:15] ERROR   : Error #10
Traceback (most recent call last):
  File "C:\Users\Алим\Desktop\sketal-master\handler\handler_controller.py", line 32, in process
    res = await self.core_process(msg)
  File "C:\Users\Алим\Desktop\sketal-master\handler\handler_controller.py", line 59, in core_process
    subres = await self.process_with_plugin(msg, plugin)
  File "C:\Users\Алим\Desktop\sketal-master\handler\handler_controller.py", line 72, in process_with_plugin
    result = await plugin.process_message(msg)
  File "C:\Users\Алим\Desktop\sketal-master\plugins\multiuser\chat_random_pair.py", line 31, in process_message
    await msg.answer(f"[id{love1['id']}|{love1['first_name']} {love1['last_name']}] - {self.text} - "
KeyError: 'first_name'

[21.08.12 11:37:32] ERROR   : Error #12
Traceback (most recent call last):
  File "C:\Users\Алим\Desktop\sketal-master\handler\handler_controller.py", line 32, in process
    res = await self.core_process(msg)
  File "C:\Users\Алим\Desktop\sketal-master\handler\handler_controller.py", line 59, in core_process
    subres = await self.process_with_plugin(msg, plugin)
  File "C:\Users\Алим\Desktop\sketal-master\handler\handler_controller.py", line 72, in process_with_plugin
    result = await plugin.process_message(msg)
  File "C:\Users\Алим\Desktop\sketal-master\plugins\multiuser\chat_random_pair.py", line 31, in process_message
    await msg.answer(f"[id{love1['id']}|{love1['first_name']} {love1['last_name']}] - {self.text} - "
KeyError: 'first_name'

[21.08.12 11:39:58] ERROR   : Error #13
Traceback (most recent call last):
  File "C:\Users\Алим\Desktop\sketal-master\handler\handler_controller.py", line 32, in process
    res = await self.core_process(msg)
  File "C:\Users\Алим\Desktop\sketal-master\handler\handler_controller.py", line 59, in core_process
    subres = await self.process_with_plugin(msg, plugin)
  File "C:\Users\Алим\Desktop\sketal-master\handler\handler_controller.py", line 72, in process_with_plugin
    result = await plugin.process_message(msg)
  File "C:\Users\Алим\Desktop\sketal-master\plugins\multiuser\chat_random_pair.py", line 31, in process_message
    await msg.answer(f"[id{love1['id']}|{love1['first_name']} {love1['last_name']}] - {self.text} - "
KeyError: 'first_name'

[21.08.12 11:45:38] ERROR   : Error #15
Traceback (most recent call last):
  File "C:\Users\Алим\Desktop\sketal-master\handler\handler_controller.py", line 32, in process
    res = await self.core_process(msg)
  File "C:\Users\Алим\Desktop\sketal-master\handler\handler_controller.py", line 59, in core_process
    subres = await self.process_with_plugin(msg, plugin)
  File "C:\Users\Алим\Desktop\sketal-master\handler\handler_controller.py", line 72, in process_with_plugin
    result = await plugin.process_message(msg)
  File "C:\Users\Алим\Desktop\sketal-master\plugins\multiuser\chat_random_pair.py", line 31, in process_message
    await msg.answer(f"[id{love1['id']}|{love1['first_name']} {love1['last_name']}] - {self.text} - "
KeyError: 'first_name'

[21.08.12 13:04:21] INFO    : Initializing bot
[21.08.12 13:04:21] INFO    : Initializing vk clients
[21.08.12 13:04:22] INFO    : Logged in as: Иван Иваненко (https://vk.com/id537489641)
[21.08.12 13:04:22] INFO    : Loading plugins
[21.08.12 13:04:22] WARNING : No key specified for Yandex Speechkit Cloud. Google will be used. You can get your key - https://tech.yandex.ru/speechkit/cloud/.
[21.08.12 13:04:22] INFO    : Bot successfully initialized
[21.08.12 13:04:22] INFO    : Started to process messages
[21.08.12 13:09:21] INFO    : Attempting to turn bot off
[21.08.12 13:09:50] INFO    : Initializing bot
[21.08.12 13:09:50] INFO    : Initializing vk clients
[21.08.12 13:09:51] INFO    : Logged in as: Иван Иваненко (https://vk.com/id537489641)
[21.08.12 13:09:51] INFO    : Loading plugins
[21.08.12 13:09:51] WARNING : No key specified for Yandex Speechkit Cloud. Google will be used. You can get your key - https://tech.yandex.ru/speechkit/cloud/.
[21.08.12 13:09:51] INFO    : Bot successfully initialized
[21.08.12 13:09:51] INFO    : Started to process messages
[21.08.12 13:22:51] INFO    : Initializing bot
[21.08.12 13:22:51] INFO    : Initializing vk clients
[21.08.12 13:22:52] INFO    : Logged in as: Иван Иваненко (https://vk.com/id537489641)
[21.08.12 13:22:52] INFO    : Loading plugins
[21.08.12 13:22:52] WARNING : No key specified for Yandex Speechkit Cloud. Google will be used. You can get your key - https://tech.yandex.ru/speechkit/cloud/.
[21.08.12 13:22:52] INFO    : Bot successfully initialized
[21.08.12 13:22:52] INFO    : Started to process messages
[21.08.12 13:24:12] INFO    : Initializing bot
[21.08.12 13:24:12] INFO    : Initializing vk clients
[21.08.12 13:24:12] INFO    : Logged in as: Иван Иваненко (https://vk.com/id537489641)
[21.08.12 13:24:12] INFO    : Loading plugins
[21.08.12 13:24:12] WARNING : No key specified for Yandex Speechkit Cloud. Google will be used. You can get your key - https://tech.yandex.ru/speechkit/cloud/.
[21.08.12 13:24:12] INFO    : Bot successfully initialized
[21.08.12 13:24:12] INFO    : Started to process messages
[21.08.12 13:25:04] INFO    : Initializing bot
[21.08.12 13:25:04] INFO    : Initializing vk clients
[21.08.12 13:25:04] INFO    : Logged in as: Иван Иваненко (https://vk.com/id537489641)
[21.08.12 13:25:04] INFO    : Loading plugins
[21.08.12 13:25:04] WARNING : No key specified for Yandex Speechkit Cloud. Google will be used. You can get your key - https://tech.yandex.ru/speechkit/cloud/.
[21.08.12 13:25:04] INFO    : Bot successfully initialized
[21.08.12 13:25:04] INFO    : Started to process messages
[21.08.12 13:36:27] INFO    : Initializing bot
[21.08.12 13:36:27] INFO    : Initializing vk clients
[21.08.12 13:36:28] INFO    : Logged in as: Иван Иваненко (https://vk.com/id537489641)
[21.08.12 13:36:28] INFO    : Loading plugins
[21.08.12 13:36:28] WARNING : No key specified for Yandex Speechkit Cloud. Google will be used. You can get your key - https://tech.yandex.ru/speechkit/cloud/.
[21.08.12 13:36:28] INFO    : Bot successfully initialized
[21.08.12 13:36:28] INFO    : Started to process messages
[21.08.12 13:37:56] INFO    : Initializing bot
[21.08.12 13:37:56] INFO    : Initializing vk clients
[21.08.12 13:37:56] INFO    : Logged in as: Иван Иваненко (https://vk.com/id537489641)
[21.08.12 13:37:57] INFO    : Loading plugins
[21.08.12 13:37:57] WARNING : No key specified for Yandex Speechkit Cloud. Google will be used. You can get your key - https://tech.yandex.ru/speechkit/cloud/.
[21.08.12 13:37:57] INFO    : Bot successfully initialized
[21.08.12 13:37:57] INFO    : Started to process messages
[21.08.12 13:42:02] INFO    : Initializing bot
[21.08.12 13:42:02] INFO    : Initializing vk clients
[21.08.12 13:42:02] INFO    : Logged in as: Иван Иваненко (https://vk.com/id537489641)
[21.08.12 13:42:02] INFO    : Loading plugins
[21.08.12 13:42:02] WARNING : No key specified for Yandex Speechkit Cloud. Google will be used. You can get your key - https://tech.yandex.ru/speechkit/cloud/.
[21.08.12 13:42:02] INFO    : Bot successfully initialized
[21.08.12 13:42:03] INFO    : Started to process messages
[21.08.12 13:44:11] INFO    : Initializing bot
[21.08.12 13:44:11] INFO    : Initializing vk clients
[21.08.12 13:44:11] INFO    : Logged in as: Иван Иваненко (https://vk.com/id537489641)
[21.08.12 13:44:11] INFO    : Loading plugins
[21.08.12 13:44:11] WARNING : No key specified for Yandex Speechkit Cloud. Google will be used. You can get your key - https://tech.yandex.ru/speechkit/cloud/.
[21.08.12 13:44:11] INFO    : Bot successfully initialized
[21.08.12 13:44:11] INFO    : Started to process messages
[21.08.12 13:45:06] INFO    : Initializing bot
[21.08.12 13:45:06] INFO    : Initializing vk clients
[21.08.12 13:45:06] INFO    : Logged in as: Иван Иваненко (https://vk.com/id537489641)
[21.08.12 13:45:06] INFO    : Loading plugins
[21.08.12 13:45:06] WARNING : No key specified for Yandex Speechkit Cloud. Google will be used. You can get your key - https://tech.yandex.ru/speechkit/cloud/.
[21.08.12 13:45:06] INFO    : Bot successfully initialized
[21.08.12 13:45:06] INFO    : Started to process messages
[21.08.12 13:47:54] INFO    : Initializing bot
[21.08.12 13:47:54] INFO    : Initializing vk clients
[21.08.12 13:47:55] INFO    : Logged in as: Иван Иваненко (https://vk.com/id537489641)
[21.08.12 13:47:55] INFO    : Loading plugins
[21.08.12 13:47:55] WARNING : No key specified for Yandex Speechkit Cloud. Google will be used. You can get your key - https://tech.yandex.ru/speechkit/cloud/.
[21.08.12 13:47:55] INFO    : Bot successfully initialized
[21.08.12 13:47:55] INFO    : Started to process messages
[21.08.12 13:50:13] ERROR   : Errors while executing vk method:
{'error_code': 15, 'method': 'messages.addChatUser', 'error_msg': "Access denied: can't add this user"}
[21.08.12 13:56:51] ERROR   : Error #1
Traceback (most recent call last):
  File "C:\Users\Алим\AppData\Local\Programs\Python\Python38\lib\site-packages\aiohttp\connector.py", line 969, in _wrap_create_connection
    return await self._loop.create_connection(*args, **kwargs)  # type: ignore  # noqa
  File "C:\Users\Алим\AppData\Local\Programs\Python\Python38\lib\asyncio\base_events.py", line 1050, in create_connection
    transport, protocol = await self._create_connection_transport(
  File "C:\Users\Алим\AppData\Local\Programs\Python\Python38\lib\asyncio\base_events.py", line 1080, in _create_connection_transport
    await waiter
ConnectionResetError

The above exception was the direct cause of the following exception:

Traceback (most recent call last):
  File "C:\Users\Алим\Desktop\sketal-master\handler\handler_controller.py", line 32, in process
    res = await self.core_process(msg)
  File "C:\Users\Алим\Desktop\sketal-master\handler\handler_controller.py", line 59, in core_process
    subres = await self.process_with_plugin(msg, plugin)
  File "C:\Users\Алим\Desktop\sketal-master\handler\handler_controller.py", line 72, in process_with_plugin
    result = await plugin.process_message(msg)
  File "C:\Users\Алим\Desktop\sketal-master\plugins\outsource\outsource_faceapp.py", line 102, in process_message
    async with sess.post(BASE_API_URL, headers=headers, data={'file': image}) as resp:
  File "C:\Users\Алим\AppData\Local\Programs\Python\Python38\lib\site-packages\aiohttp\client.py", line 1117, in __aenter__
    self._resp = await self._coro
  File "C:\Users\Алим\AppData\Local\Programs\Python\Python38\lib\site-packages\aiohttp\client.py", line 520, in _request
    conn = await self._connector.connect(
  File "C:\Users\Алим\AppData\Local\Programs\Python\Python38\lib\site-packages\aiohttp\connector.py", line 535, in connect
    proto = await self._create_connection(req, traces, timeout)
  File "C:\Users\Алим\AppData\Local\Programs\Python\Python38\lib\site-packages\aiohttp\connector.py", line 892, in _create_connection
    _, proto = await self._create_direct_connection(req, traces, timeout)
  File "C:\Users\Алим\AppData\Local\Programs\Python\Python38\lib\site-packages\aiohttp\connector.py", line 1051, in _create_direct_connection
    raise last_exc
  File "C:\Users\Алим\AppData\Local\Programs\Python\Python38\lib\site-packages\aiohttp\connector.py", line 1020, in _create_direct_connection
    transp, proto = await self._wrap_create_connection(
  File "C:\Users\Алим\AppData\Local\Programs\Python\Python38\lib\site-packages\aiohttp\connector.py", line 975, in _wrap_create_connection
    raise client_error(req.connection_key, exc) from exc
aiohttp.client_exceptions.ClientConnectorError: Cannot connect to host node-01.faceapp.io:443 ssl:default [None]

[21.08.12 13:58:53] INFO    : Initializing bot
[21.08.12 13:58:53] INFO    : Initializing vk clients
[21.08.12 13:58:53] INFO    : Logged in as: Иван Иваненко (https://vk.com/id537489641)
[21.08.12 13:58:53] INFO    : Loading plugins
[21.08.12 13:58:53] WARNING : No key specified for Yandex Speechkit Cloud. Google will be used. You can get your key - https://tech.yandex.ru/speechkit/cloud/.
[21.08.12 13:58:53] INFO    : Bot successfully initialized
[21.08.12 13:58:53] INFO    : Started to process messages
[21.08.12 14:02:18] ERROR   : Error #1
Traceback (most recent call last):
  File "C:\Users\Алим\AppData\Local\Programs\Python\Python38\lib\site-packages\aiohttp\connector.py", line 969, in _wrap_create_connection
    return await self._loop.create_connection(*args, **kwargs)  # type: ignore  # noqa
  File "C:\Users\Алим\AppData\Local\Programs\Python\Python38\lib\asyncio\base_events.py", line 1050, in create_connection
    transport, protocol = await self._create_connection_transport(
  File "C:\Users\Алим\AppData\Local\Programs\Python\Python38\lib\asyncio\base_events.py", line 1080, in _create_connection_transport
    await waiter
ConnectionResetError

The above exception was the direct cause of the following exception:

Traceback (most recent call last):
  File "C:\Users\Алим\Desktop\sketal-master\handler\handler_controller.py", line 32, in process
    res = await self.core_process(msg)
  File "C:\Users\Алим\Desktop\sketal-master\handler\handler_controller.py", line 59, in core_process
    subres = await self.process_with_plugin(msg, plugin)
  File "C:\Users\Алим\Desktop\sketal-master\handler\handler_controller.py", line 72, in process_with_plugin
    result = await plugin.process_message(msg)
  File "C:\Users\Алим\Desktop\sketal-master\plugins\outsource\outsource_faceapp.py", line 102, in process_message
    async with sess.post(BASE_API_URL, headers=headers, data={'file': image}) as resp:
  File "C:\Users\Алим\AppData\Local\Programs\Python\Python38\lib\site-packages\aiohttp\client.py", line 1117, in __aenter__
    self._resp = await self._coro
  File "C:\Users\Алим\AppData\Local\Programs\Python\Python38\lib\site-packages\aiohttp\client.py", line 520, in _request
    conn = await self._connector.connect(
  File "C:\Users\Алим\AppData\Local\Programs\Python\Python38\lib\site-packages\aiohttp\connector.py", line 535, in connect
    proto = await self._create_connection(req, traces, timeout)
  File "C:\Users\Алим\AppData\Local\Programs\Python\Python38\lib\site-packages\aiohttp\connector.py", line 892, in _create_connection
    _, proto = await self._create_direct_connection(req, traces, timeout)
  File "C:\Users\Алим\AppData\Local\Programs\Python\Python38\lib\site-packages\aiohttp\connector.py", line 1051, in _create_direct_connection
    raise last_exc
  File "C:\Users\Алим\AppData\Local\Programs\Python\Python38\lib\site-packages\aiohttp\connector.py", line 1020, in _create_direct_connection
    transp, proto = await self._wrap_create_connection(
  File "C:\Users\Алим\AppData\Local\Programs\Python\Python38\lib\site-packages\aiohttp\connector.py", line 975, in _wrap_create_connection
    raise client_error(req.connection_key, exc) from exc
aiohttp.client_exceptions.ClientConnectorError: Cannot connect to host node-01.faceapp.io:443 ssl:default [None]

[21.08.12 21:12:38] INFO    : Initializing bot
[21.08.12 21:12:38] INFO    : Initializing vk clients
[21.08.12 21:12:39] INFO    : Logged in as: Иван Иваненко (https://vk.com/id537489641)
[21.08.12 21:12:39] INFO    : Loading plugins
[21.08.12 21:12:39] WARNING : No key specified for Yandex Speechkit Cloud. Google will be used. You can get your key - https://tech.yandex.ru/speechkit/cloud/.
[21.08.12 21:12:39] INFO    : Bot successfully initialized
[21.08.12 21:12:39] INFO    : Started to process messages
[21.08.12 22:21:00] INFO    : Initializing bot
[21.08.12 22:21:00] INFO    : Initializing vk clients
[21.08.12 22:21:00] INFO    : Logged in as: Иван Иваненко (https://vk.com/id537489641)
[21.08.12 22:21:00] INFO    : Loading plugins
[21.08.12 22:21:00] WARNING : No key specified for Yandex Speechkit Cloud. Google will be used. You can get your key - https://tech.yandex.ru/speechkit/cloud/.
[21.08.12 22:21:00] INFO    : Bot successfully initialized
[21.08.12 22:21:00] INFO    : Started to process messages
[21.08.12 22:28:46] ERROR   : Errors while executing vk method:
{'error_code': 100, 'method': 'messages.send', 'error_msg': 'One of the parameters specified was missing or invalid: message is empty or invalid'}
{'error_code': 100, 'method': 'messages.send', 'error_msg': 'One of the parameters specified was missing or invalid: message is empty or invalid'}
{'error_code': 100, 'method': 'messages.send', 'error_msg': 'One of the parameters specified was missing or invalid: message is empty or invalid'}
{'error_code': 100, 'method': 'messages.send', 'error_msg': 'One of the parameters specified was missing or invalid: message is empty or invalid'}
[21.08.12 22:31:10] WARNING : Enter information for captcha solving in settings.py
[21.08.12 22:35:04] INFO    : Initializing bot
[21.08.12 22:35:04] INFO    : Initializing vk clients
[21.08.12 22:35:05] INFO    : Logged in as: Иван Иваненко (https://vk.com/id537489641)
[21.08.12 22:35:05] INFO    : Loading plugins
[21.08.12 22:35:05] WARNING : No key specified for Yandex Speechkit Cloud. Google will be used. You can get your key - https://tech.yandex.ru/speechkit/cloud/.
[21.08.12 22:35:05] INFO    : Bot successfully initialized
[21.08.12 22:35:05] INFO    : Started to process messages
[21.08.12 22:42:55] INFO    : Initializing bot
[21.08.12 22:42:55] INFO    : Initializing vk clients
[21.08.12 22:42:55] INFO    : Logged in as: Иван Иваненко (https://vk.com/id537489641)
[21.08.12 22:42:55] INFO    : Loading plugins
[21.08.12 22:42:55] WARNING : No key specified for Yandex Speechkit Cloud. Google will be used. You can get your key - https://tech.yandex.ru/speechkit/cloud/.
[21.08.12 22:42:55] INFO    : Bot successfully initialized
[21.08.12 22:42:55] INFO    : Started to process messages
[21.08.12 22:44:39] INFO    : Initializing bot
[21.08.12 22:44:39] INFO    : Initializing vk clients
[21.08.12 22:44:40] INFO    : Logged in as: Иван Иваненко (https://vk.com/id537489641)
[21.08.12 22:44:40] INFO    : Loading plugins
[21.08.12 22:44:40] WARNING : No key specified for Yandex Speechkit Cloud. Google will be used. You can get your key - https://tech.yandex.ru/speechkit/cloud/.
[21.08.12 22:44:40] INFO    : Bot successfully initialized
[21.08.12 22:44:40] INFO    : Started to process messages
[21.08.12 22:47:59] INFO    : Initializing bot
[21.08.12 22:47:59] INFO    : Initializing vk clients
[21.08.12 22:48:30] INFO    : Initializing bot
[21.08.12 22:48:30] INFO    : Initializing vk clients
[21.08.12 22:48:31] INFO    : Logged in as: Иван Иваненко (https://vk.com/id537489641)
[21.08.12 22:48:31] INFO    : Loading plugins
[21.08.12 22:48:31] WARNING : No key specified for Yandex Speechkit Cloud. Google will be used. You can get your key - https://tech.yandex.ru/speechkit/cloud/.
[21.08.12 22:48:31] INFO    : Bot successfully initialized
[21.08.12 22:48:31] INFO    : Started to process messages
[21.08.12 22:56:03] INFO    : Initializing bot
[21.08.12 22:56:03] INFO    : Initializing vk clients
[21.08.12 22:56:03] INFO    : Logged in as: Иван Иваненко (https://vk.com/id537489641)
[21.08.12 22:56:03] INFO    : Loading plugins
[21.08.12 22:56:03] WARNING : No key specified for Yandex Speechkit Cloud. Google will be used. You can get your key - https://tech.yandex.ru/speechkit/cloud/.
[21.08.12 22:56:03] INFO    : Bot successfully initialized
[21.08.12 22:56:03] INFO    : Started to process messages
[21.08.12 23:05:30] INFO    : Initializing bot
[21.08.12 23:05:30] INFO    : Initializing vk clients
[21.08.12 23:05:31] INFO    : Logged in as: Иван Иваненко (https://vk.com/id537489641)
[21.08.12 23:05:31] INFO    : Loading plugins
[21.08.12 23:05:31] WARNING : No key specified for Yandex Speechkit Cloud. Google will be used. You can get your key - https://tech.yandex.ru/speechkit/cloud/.
[21.08.12 23:05:31] INFO    : Bot successfully initialized
[21.08.12 23:05:31] INFO    : Started to process messages
[21.08.12 23:20:07] ERROR   : Errors while executing vk method:
{'error_code': 15, 'method': 'wall.get', 'error_msg': 'Access denied: this wall available only for community members'}
[21.08.12 23:20:53] ERROR   : Errors while executing vk method:
{'error_code': 15, 'method': 'wall.get', 'error_msg': 'Access denied: this wall available only for community members'}
[21.08.13 10:11:17] INFO    : Initializing bot
[21.08.13 10:11:17] INFO    : Initializing vk clients
[21.08.13 10:11:17] INFO    : Logged in as: Алим Валиулин (https://vk.com/id537489641)
[21.08.13 10:11:17] INFO    : Loading plugins
[21.08.13 10:11:17] WARNING : No key specified for Yandex Speechkit Cloud. Google will be used. You can get your key - https://tech.yandex.ru/speechkit/cloud/.
[21.08.13 10:11:17] INFO    : Bot successfully initialized
[21.08.13 10:11:17] INFO    : Started to process messages
